# 2019-8-29

`Promise.prototype.then()` 的作用是为 `Promise` 实例添加状态改变时的回调函数，返回的是一个新的 `Promise` 实例，所以可以再次链式调用 `then` 方法，前一个 `then` 的返回值为后一个 `then` 的参数

```JavaScript
getJSON("/posts.json").then(function(json) {
  return json.post;
}).then(function(post) {
  // ...
});
```

采用链式的 `then`，可以指定一组按照次序调用的回调函数。这时，前一个回调函数，有可能返回的还是一个 `Promise` 对象（即有异步操作），这时后一个回调函数，就会等待该 `Promise` 对象的状态发生变化，才会被调用，并且根据变化后的状态，调用不同的回调函数，这个点和之前的 `resolve` 一个 `Promise` 对象一样

```JavaScript
getJSON("/post/1.json").then(function(post) {
  return getJSON(post.commentURL);
}).then(function (comments) {
  console.log("resolved: ", comments);
}, function (err){
  console.log("rejected: ", err);
});
```

`Promise.prototype.catch()` 是 `.then(null, rejection)` 或 `.then(undefined, rejection)` 的别名，用于指定发生错误时的回调函数，并且 `then` 方法指定的回调函数运行中发生错误，也会被 `catch` 方法捕获，如果 Promise 状态已经变成 `resolved`，再抛出错误是无效的

```JavaScript
getJSON('/posts.json').then(function(posts) {
  // ...
}).catch(function(error) {
  // 处理 getJSON 和 前一个回调函数运行时发生的错误
  console.log('发生错误！', error);
});

const promise = new Promise(function(resolve, reject) {
  throw new Error('test');
});
promise.catch(function(error) {
  console.log(error);
});
// Error: test

const promise = new Promise(function(resolve, reject) {
  resolve('ok');
  throw new Error('test');
});
promise
  .then(function(value) { console.log(value) })
  .catch(function(error) { console.log(error) });
// ok
```

有三种等价的写法可以了解一下

```JavaScript
// 写法一
const promise = new Promise(function(resolve, reject) {
  throw new Error('test');
});
promise.catch(function(error) {
  console.log(error);
});
// Error: test

// 写法二
const promise = new Promise(function(resolve, reject) {
  try {
    throw new Error('test');
  } catch(e) {
    reject(e);
  }
});
promise.catch(function(error) {
  console.log(error);
});

// 写法三
const promise = new Promise(function(resolve, reject) {
  reject(new Error('test'));
});
promise.catch(function(error) {
  console.log(error);
});
```

错误使用 `Error` 实例是比较规范的做法，而在 `Promise` 实例中，`reject` 等同于抛出错误，所以如何抛出一个错误，看需求

Promise 对象的错误具有“冒泡”性质，会一直向后传递，直到被捕获为止，也就是说，错误总是会被下一个 `catch` 语句捕获，这个特性也就意味着，多个 `Promise` 实例中的报错，可以在一个 `catch` 中处理

```JavaScript
getJSON('/post/1.json').then(function(post) {
  return getJSON(post.commentURL);
}).then(function(comments) {
  // some code
}).catch(function(error) {
  // 处理前面三个Promise产生的错误
});
```

一般来说，虽然 `then` 方法里可以定义 Reject 状态的回调函数，但还是使用 `catch` 方法，因为 `catch` 不仅能处理 `Promise` 实例中同步代码的错误，还能处理 `then` 方法中的错误，也更接近 `try/catch` 的写法，与 `try/catch` 不同的是，如果 `Promise` 实例不使用 `catch` 方法指定错误处理的回调函数，那么这其中抛出的错误不会传递到外层代码中，即不会有任何影响

```JavaScript
const someAsyncThing = function() {
  return new Promise(function(resolve, reject) {
    // 下面一行会报错，因为x没有声明
    resolve(x + 2);
  });
};

someAsyncThing().then(function() {
  console.log('everything is great');
});

setTimeout(() => { console.log(123) }, 2000);
// Uncaught (in promise) ReferenceError: x is not defined
// 123
```

`someAsyncThing` 函数产生的 `Promise` 对象，内部有语法错误，浏览器运行到这一行，会打印出错误提示 `ReferenceError: x is not defined`，但是不会退出进程、终止脚本执行，2 秒之后还是会输出 `123`，所以 Promise 内部的错误不会影响到 Promise 外部的代码

如果在 Node 服务端，有一个 `unhandledRejection` 事件，专门监听未捕获的 `reject` 错误，上面的脚本会触发这个事件的监听函数，可以在监听函数里面抛出错误

```JavaScript
// 回调函数第一个参数是错误对象，第二个参数是报错的 Promise 实例
process.on('unhandledRejection', function (err, p) {
  throw err;
});
```

但是，Node 有计划在未来废除 `unhandledRejection` 事件，如果 Promise 内部有未捕获的错误，会直接终止进程，并且进程的退出码不为 0

再来个例子

```JavaScript
const promise = new Promise(function (resolve, reject) {
  resolve('ok');
  setTimeout(function () { throw new Error('test') }, 0)
});
promise.then(function (value) { console.log(value) });
// ok
// Uncaught Error: test
```

这段代码中，Promise 指定在下一轮“事件循环”再抛出错误，到了那个时候，Promise 的运行已经结束了，所以这个错误是在 Promise 函数体外抛出的，会冒泡到最外层，成了未捕获的错误

所以还是建议 Promise 对象后面要跟 `catch` 来处理 Promise 内部发生的错误，而且 `catch` 返回的也是一个 Promise 对象，所以后面还能再跟 `then` 和 `catch`，如果没有报错，则直接跳过这个 `catch` 去调用它之后的 `then`，而之后的 `then` 要是报错，就和跳过的这个 `catch` 没关系了

`catch` 方法之中，还能再抛出错误

```JavaScript
const someAsyncThing = function() {
  return new Promise(function(resolve, reject) {
    // 下面一行会报错，因为x没有声明
    resolve(x + 2);
  });
};

someAsyncThing().then(function() {
  return someOtherAsyncThing();
}).catch(function(error) {
  console.log('oh no', error);
  // 下面一行会报错，因为 y 没有声明
  y + 2;
}).then(function() {
  console.log('carry on');
});
// oh no [ReferenceError: x is not defined]
```

这段代码中，`catch` 方法抛出一个错误，因为后面没有别的 `catch` 方法了，导致这个错误不会被捕获，也不会传递到外层，但是可以在这个 `catch` 后面再跟一个 `catch` 来处理错误

`then` 就是 Promise 执行成功的回调，感觉也没什么很需要注意的地方，硬要说的话，就是不要使用第二个参数而是使用 `catch` 来执行 Promise 执行失败的回调，而 `catch` 还会捕获 Promise 对象中同步代码的报错，和在它之前所有 `then` 中的报错，如果没有 `catch` 则错误会影响 Promise 内部的代码运行，不会影响 Promise 外部的代码，但如果使用异步将这个报错的时间放到了下个“事件循环”，那这个错误会被抛到 Promise 外部，可以进行另外的处理，所以对于 Promise 对象的报错，有很多种处理方式，可以灵活以运用
