# 2019-10-19

虽然中途有去看 Ant Design，但还是托更了接近 40 天才回来继续看 ES6 的内容，掘金上连万字总结都出来了，哈哈哈哈哈

`Generator.prototype.throw()`，可以在函数体外抛出错误，然后在 Generator 函数体内捕获

```JavaScript
var g = function* () {
  try {
    yield;
  } catch (e) {
    console.log('内部捕获', e);
  }
};

var i = g();
i.next();

try {
  i.throw('a');
  i.throw('b');
} catch (e) {
  console.log('外部捕获', e);
}
// 内部捕获 a
// 外部捕获 b
```

遍历器对象 i 连续抛出两个错误，第一个错误被 Generator 函数体内的 `catch` 语句捕获，i 第二次抛出错误，由于内部的 `catch` 语句已经执行过，所以这个错误就被抛出了函数体，被函数体外的 `catch` 语句捕获

`throw` 方法可以接受一个参数，该参数会被 `catch` 语句接收，建议抛出 `Error` 对象的实例

如果不是使用遍历器对象的 `throw` 方法而使用全局的，那这个错误只能被函数体外的 `catch` 语句捕获，并且两者毫无关系，互不影响

如果 Generator 函数内部没有部署 `try...catch` 代码块，那么 `throw` 方法抛出的错误，将被外部 `try...catch` 代码块捕获，如果都没部署，那程序将报错，直接中断执行

而且，`throw` 方法抛出的错误要被内部捕获，前提是必须至少执行过一次 `next` 方法，因为第一次执行 `next` 方法，等同于启动执行 Generator 函数的内部代码，执行 `throw` 方法被捕获以后，会附带执行下一条 `yield` 表达式，也就是说，会附带执行一次 `next` 方法

多个 `yield` 表达式，可以只用一个 `try...catch` 代码块来捕获错误，当然，这个代码块是在 Generator 函数体内部还是包裹着几个 `next` 方法，就看自己想要怎么处理错误了

一旦 Generator 执行过程中抛出错误，且没有被内部捕获，就不会再执行下去了，如果此后还调用 `next` 方法，将返回一个 `{value : undefined, done : true}` 对象，即 JavaScript 引擎认为这个 Generator 已经运行结束了

`Generator.prototype.return()`，可以返回给定的值，并且终结遍历 Generator 函数

```JavaScript
function* gen() {
  yield 1;
  yield 2;
  yield 3;
}

var g = gen();

g.next()        // { value: 1, done: false }
g.return('foo') // { value: "foo", done: true }
g.next()        // { value: undefined, done: true }
```

如果 `return` 方法调用时，不提供参数，则返回值的 `value` 属性为 `undefined`

如果 Generator 函数内部有 `try...finally` 代码块，且正在执行 `try` 代码块，那么 `return` 方法会导致立刻进入 `finally` 代码块，执行完以后，整个函数才会结束

```JavaScript
function* numbers () {
  yield 1;
  try {
    yield 2;
    yield 3;
  } finally {
    yield 4;
    yield 5;
  }
  yield 6;
}
var g = numbers();
g.next() // { value: 1, done: false }
g.next() // { value: 2, done: false }
g.return(7) // { value: 4, done: false }
g.next() // { value: 5, done: false }
g.next() // { value: 7, done: true }
```

`next()`、`throw()`、`return()` 作用都是让 Generator 函数恢复执行，并且使用不同的语句替换 `yield` 表达式

`next()` 是将 `yield` 表达式替换成一个值，不论这个表达式做了什么，`throw()` 是将 `yield` 表达式替换成一个 `throw` 语句，`return()` 是将 `yield` 表达式替换成一个 `return` 语句，和 return 的不同可能就是 return 直接结束执行，而它如果遇到 `finally` 会墨迹到 `finally` 代码块执行完
