# 2019-11-5

`async` 函数错误处理

如果 `await` 后面的异步操作出错，那么等同于 `async` 函数返回的 Promise 对象被 `reject`，防止出错的方法，也是将其放在 `try...catch` 代码块之中，如果有多个 `await` 命令，可以统一放在 `try...catch` 结构中

```JavaScript
async function main() {
  try {
    const val1 = await firstStep();
    const val2 = await secondStep(val1);
    const val3 = await thirdStep(val1, val2);

    console.log('Final: ', val3);
  }
  catch (err) {
    console.error(err);
  }
}
```

有几个需要注意的点

其一，`await` 命令后面的 Promise 对象，运行结果可能是 `rejected`，所以最好把 `await` 命令放在 `try...catch` 代码块中，当然，也可使用 `catch` 函数

其二，多个 `await` 命令后面的异步操作，如果不存在继发关系，最好让它们同时触发，减少一些程序的执行时间，可以使用 `Promise.all()`，也可以使用将异步操作赋予变量的形式

```JavaScript
// 写法一
let [foo, bar] = await Promise.all([getFoo(), getBar()]);

// 写法二
let fooPromise = getFoo();
let barPromise = getBar();
let foo = await fooPromise;
let bar = await barPromise;
```

其三，`await` 命令只能用在 `async` 函数之中

其四，`async` 函数可以保留运行堆栈
